Workbook

Sheet dataset
A1: Department | B1: Employee ID | C1: Position | D1: Job Function | E1: № | F1: Monthly Salary | G1: Base Salary (Monthly) | H1: Security Clearance Allowance | I1: Performance Bonus | J1: Salary Indexation (8%) | K1: Annual Salary | L1: KPI Bonus (%) | M1: Annual KPI Bonus Reserve | N1: Payroll Taxes (KPI Bonus) | O1: Annual Salary + KPI Bonus | P1: Vacation Reserve | Q1: Payroll Taxes (Vacation) | R1: 11-Month Salary | S1: Payroll Taxes (Salary) | T1: Health Insurance | U1: Total Payroll | V1: Total Payroll Taxes | W1: Total Compensation Cost
A2: Administration | B2: Emp_001 | C2: Chief Executive Officer | D2: =VLOOKUP(Payroll_Data_Analysis[[#This Row],[Position]],Position_Map!$A$2:$B$58,2,FALSE) -> Executive | E2: 1 | F2: 600000 | G2: 265000 | H2: =dataset!$G2*0.1 -> 26500 | I2: =dataset!$F2-dataset!$J2-dataset!$G2-dataset!$H2 -> 287300 | J2: =dataset!$G2*0.08 -> 21200 | K2: =dataset!$F2*12 -> 7200000 | L2: =IF(dataset!$G2>=200000,38%,IF(dataset!$G2<=145000,12.3%,)) -> 0.38 | M2: =dataset!$G2*L3*12 -> 391140 | N2: =IF(Payroll_Data_Analysis[[#This Row],[Annual KPI Bonus Reserve]]<=2979000,Payroll_Data_Analysis[[#This Row],[Annual KPI Bonus Reserve]]*0.302,2979000*0.302+(Payroll_Data_Analysis[[#This Row],[Annual KPI Bonus Reserve]]-2979000)*0.151) -> 118124.28 | O2: =dataset!$K2+dataset!$M2 -> 7591140 | P2: =Payroll_Data_Analysis[[#This Row],[Annual Salary + KPI Bonus]]/12/29.3*31 -> 669298.46 | Q2: =IF(Payroll_Data_Analysis[[#This Row],[Vacation Reserve]]<=2979000,Payroll_Data_Analysis[[#This Row],[Vacation Reserve]]*0.302,2979000*0.302+(Payroll_Data_Analysis[[#This Row],[Vacation Reserve]]-2979000)*0.151) -> 202128.14 | R2: =Payroll_Data_Analysis[[#This Row],[Monthly Salary]]*11 -> 6600000 | S2: =IF(Payroll_Data_Analysis[[#This Row],[11-Month Salary]]<=2979000,Payroll_Data_Analysis[[#This Row],[11-Month Salary]]*0.302,2979000*0.302+(Payroll_Data_Analysis[[#This Row],[11-Month Salary]]-2979000)*0.151) -> 1446429 | T2: =IF(Payroll_Data_Analysis[[#This Row],[Base Salary (Monthly)]]>=200000,69507,IF(Payroll_Data_Analysis[[#This Row],[Base Salary (Monthly)]]>=145000,52684,35103)) -> 69507 | U2: =Payroll_Data_Analysis[[#This Row],[Annual KPI Bonus Reserve]]+Payroll_Data_Analysis[[#This Row],[Vacation Reserve]]+Payroll_Data_Analysis[[#This Row],[11-Month Salary]] -> 7660438.5 | V2: =Payroll_Data_Analysis[[#This Row],[Payroll Taxes (KPI Bonus)]]+Payroll_Data_Analysis[[#This Row],[Payroll Taxes (Vacation)]]+Payroll_Data_Analysis[[#This Row],[Payroll Taxes (Salary)]] -> 1766681.4 | W2: =Payroll_Data_Analysis[[#This Row],[Total Payroll]]+Payroll_Data_Analysis[[#This Row],[Total Payroll Taxes]] -> 9427119.9
A3: Administration | B3: Emp_002 | C3: Assistant | D3: =VLOOKUP(Payroll_Data_Analysis[[#This Row],[Position]],Position_Map!$A$2:$B$58,2,FALSE) -> Administration | E3: 1 | F3: 231600 | G3: 145000 | I3: =dataset!$F3-dataset!$J3-dataset!$G3-dataset!$H3 -> 75000 | J3: =dataset!$G3*0.08 -> 11600 | K3: =dataset!$F3*12 -> 2779200 | L3: =IF(dataset!$G3>=200000,38%,IF(dataset!$G3<=145000,12.3%,)) -> 0.123 | M3: =dataset!$G3*L4*12 -> 214020 | N3: =IF(Payroll_Data_Analysis[[#This Row],[Annual KPI Bonus Reserve]]<=2979000,Payroll_Data_Analysis[[#This Row],[Annual KPI Bonus Reserve]]*0.302,2979000*0.302+(Payroll_Data_Analysis[[#This Row],[Annual KPI Bonus Reserve]]-2979000)*0.151) -> 64634.04 | O3: =dataset!$K3+dataset!$M3 -> 2993220 | P3: =Payroll_Data_Analysis[[#This Row],[Annual Salary + KPI Bonus]]/12/29.3*31 -> 263907.34 | Q3: =IF(Payroll_Data_Analysis[[#This Row],[Vacation Reserve]]<=2979000,Payroll_Data_Analysis[[#This Row],[Vacation Reserve]]*0.302,2979000*0.302+(Payroll_Data_Analysis[[#This Row],[Vacation Reserve]]-2979000)*0.151) -> 79700.016 | R3: =Payroll_Data_Analysis[[#This Row],[Monthly Salary]]*11 -> 2547600 | S3: =IF(Payroll_Data_Analysis[[#This Row],[11-Month Salary]]<=2979000,Payroll_Data_Analysis[[#This Row],[11-Month Salary]]*0.302,2979000*0.302+(Payroll_Data_Analysis[[#This Row],[11-Month Salary]]-2979000)*0.151) -> 769375.2 | T3: =IF(Payroll_Data_Analysis[[#This Row],[Base Salary (Monthly)]]>=200000,69507,IF(Payroll_Data_Analysis[[#This Row],[Base Salary (Monthly)]]>=145000,52684,35103)) -> 52684 | U3: =Payroll_Data_Analysis[[#This Row],[Annual KPI Bonus Reserve]]+Payroll_Data_Analysis[[#This Row],[Vacation Reserve]]+Payroll_Data_Analysis[[#This Row],[11-Month Salary]] -> 3025527.3 | V3: =Payroll_Data_Analysis[[#This Row],[Payroll Taxes (KPI Bonus)]]+Payroll_Data_Analysis[[#This Row],[Payroll Taxes (Vacation)]]+Payroll_Data_Analysis[[#This Row],[Payroll Taxes (Salary)]] -> 913709.26 | W3: =Payroll_Data_Analysis[[#This Row],[Total Payroll]]+Payroll_Data_Analysis[[#This Row],[Total Payroll Taxes]] -> 3939236.6
A4: Administration | B4: Emp_003 | C4: Advisor | D4: =VLOOKUP(Payroll_Data_Analysis[[#This Row],[Position]],Position_Map!$A$2:$B$58,2,FALSE) -> Professional | E4: 1 | F4: 288000 | G4: 145000 | I4: =dataset!$F4-dataset!$J4-dataset!$G4-dataset!$H4 -> 131400 | J4: =dataset!$G4*0.08 -> 11600 | K4: =dataset!$F4*12 -> 3456000 | L4: =IF(dataset!$G4>=200000,38%,IF(dataset!$G4<=145000,12.3%,)) -> 0.123 | M4: =dataset!$G4*L5*12 -> 214020 | N4: =IF(Payroll_Data_Analysis[[#This Row],[Annual KPI Bonus Reserve]]<=2979000,Payroll_Data_Analysis[[#This Row],[Annual KPI Bonus Reserve]]*0.302,2979000*0.302+(Payroll_Data_Analysis[[#This Row],[Annual KPI Bonus Reserve]]-2979000)*0.151) -> 64634.04 | O4: =dataset!$K4+dataset!$M4 -> 3670020 | P4: =Payroll_Data_Analysis[[#This Row],[Annual Salary + KPI Bonus]]/12/29.3*31 -> 323579.69 | Q4: =IF(Payroll_Data_Analysis[[#This Row],[Vacation Reserve]]<=2979000,Payroll_Data_Analysis[[#This Row],[Vacation Reserve]]*0.302,2979000*0.302+(Payroll_Data_Analysis[[#This Row],[Vacation Reserve]]-2979000)*0.151) -> 97721.067 | R4: =Payroll_Data_Analysis[[#This Row],[Monthly Salary]]*11 -> 3168000 | S4: =IF(Payroll_Data_Analysis[[#This Row],[11-Month Salary]]<=2979000,Payroll_Data_Analysis[[#This Row],[11-Month Salary]]*0.302,2979000*0.302+(Payroll_Data_Analysis[[#This Row],[11-Month Salary]]-2979000)*0.151) -> 928197 | T4: =IF(Payroll_Data_Analysis[[#This Row],[Base Salary (Monthly)]]>=200000,69507,IF(Payroll_Data_Analysis[[#This Row],[Base Salary (Monthly)]]>=145000,52684,35103)) -> 52684 | U4: =Payroll_Data_Analysis[[#This Row],[Annual KPI Bonus Reserve]]+Payroll_Data_Analysis[[#This Row],[Vacation Reserve]]+Payroll_Data_Analysis[[#This Row],[11-Month Salary]] -> 3705599.7 | V4: =Payroll_Data_Analysis[[#This Row],[Payroll Taxes (KPI Bonus)]]+Payroll_Data_Analysis[[#This Row],[Payroll Taxes (Vacation)]]+Payroll_Data_Analysis[[#This Row],[Payroll Taxes (Salary)]] -> 1090552.1 | W4: =Payroll_Data_Analysis[[#This Row],[Total Payroll]]+Payroll_Data_Analysis[[#This Row],[Total Payroll Taxes]] -> 4796151.8
A5: Administration | B5: Emp_004 | C5: Advisor | D5: =VLOOKUP(Payroll_Data_Analysis[[#This Row],[Position]],Position_Map!$A$2:$B$58,2,FALSE) -> Professional | E5: 1 | F5: 120000 | G5: 100000 | I5: =dataset!$F5-dataset!$J5-dataset!$G5-dataset!$H5 -> 12000 | J5: =dataset!$G5*0.08 -> 8000 | K5: =dataset!$F5*12 -> 1440000 | L5: =IF(dataset!$G5>=200000,38%,IF(dataset!$G5<=145000,12.3%,)) -> 0.123 | M5: =dataset!$G5*L6*12 -> 456000 | N5: =IF(Payroll_Data_Analysis[[#This Row],[Annual KPI Bonus Reserve]]<=2979000,Payroll_Data_Analysis[[#This Row],[Annual KPI Bonus Reserve]]*0.302,2979000*0.302+(Payroll_Data_Analysis[[#This Row],[Annual KPI Bonus Reserve]]-2979000)*0.151) -> 137712 | O5: =dataset!$K5+dataset!$M5 -> 1896000 | P5: =Payroll_Data_Analysis[[#This Row],[Annual Salary + KPI Bonus]]/12/29.3*31 -> 167167.24 | Q5: =IF(Payroll_Data_Analysis[[#This Row],[Vacation Reserve]]<=2979000,Payroll_Data_Analysis[[#This Row],[Vacation Reserve]]*0.302,2979000*0.302+(Payroll_Data_Analysis[[#This Row],[Vacation Reserve]]-2979000)*0.151) -> 50484.505 | R5: =Payroll_Data_Analysis[[#This Row],[Monthly Salary]]*11 -> 1320000 | S5: =IF(Payroll_Data_Analysis[[#This Row],[11-Month Salary]]<=2979000,Payroll_Data_Analysis[[#This Row],[11-Month Salary]]*0.302,2979000*0.302+(Payroll_Data_Analysis[[#This Row],[11-Month Salary]]-2979000)*0.151) -> 398640 | T5: =IF(Payroll_Data_Analysis[[#This Row],[Base Salary (Monthly)]]>=200000,69507,IF(Payroll_Data_Analysis[[#This Row],[Base Salary (Monthly)]]>=145000,52684,35103)) -> 35103 | U5: =Payroll_Data_Analysis[[#This Row],[Annual KPI Bonus Reserve]]+Payroll_Data_Analysis[[#This Row],[Vacation Reserve]]+Payroll_Data_Analysis[[#This Row],[11-Month Salary]] -> 1943167.2 | V5: =Payroll_Data_Analysis[[#This Row],[Payroll Taxes (KPI Bonus)]]+Payroll_Data_Analysis[[#This Row],[Payroll Taxes (Vacation)]]+Payroll_Data_Analysis[[#This Row],[Payroll Taxes (Salary)]] -> 586836.51 | W5: =Payroll_Data_Analysis[[#This Row],[Total Payroll]]+Payroll_Data_Analysis[[#This Row],[Total Payroll Taxes]] -> 2530003.7
A6: Administration | B6: Emp_005 | C6: First Deputy CEO – Department Director | D6: =VLOOKUP(Payroll_Data_Analysis[[#This Row],[Position]],Position_Map!$A$2:$B$58,2,FALSE) -> Executive | E6: 1 | F6: 396000 | G6: 200000 | I6: =dataset!$F6-dataset!$J6-dataset!$G6-dataset!$H6 -> 180000 | J6: =dataset!$G6*0.08 -> 16000 | K6: =dataset!$F6*12 -> 4752000 | L6: =IF(dataset!$G6>=200000,38%,IF(dataset!$G6<=145000,12.3%,)) -> 0.38 | M6: =dataset!$G6*L7*12 -> 912000 | N6: =IF(Payroll_Data_Analysis[[#This Row],[Annual KPI Bonus Reserve]]<=2979000,Payroll_Data_Analysis[[#This Row],[Annual KPI Bonus Reserve]]*0.302,2979000*0.302+(Payroll_Data_Analysis[[#This Row],[Annual KPI Bonus Reserve]]-2979000)*0.151) -> 275424 | O6: =dataset!$K6+dataset!$M6 -> 5664000 | P6: =Payroll_Data_Analysis[[#This Row],[Annual Salary + KPI Bonus]]/12/29.3*31 -> 499385.67 | Q6: =IF(Payroll_Data_Analysis[[#This Row],[Vacation Reserve]]<=2979000,Payroll_Data_Analysis[[#This Row],[Vacation Reserve]]*0.302,2979000*0.302+(Payroll_Data_Analysis[[#This Row],[Vacation Reserve]]-2979000)*0.151) -> 150814.47 | R6: =Payroll_Data_Analysis[[#This Row],[Monthly Salary]]*11 -> 4356000 | S6: =IF(Payroll_Data_Analysis[[#This Row],[11-Month Salary]]<=2979000,Payroll_Data_Analysis[[#This Row],[11-Month Salary]]*0.302,2979000*0.302+(Payroll_Data_Analysis[[#This Row],[11-Month Salary]]-2979000)*0.151) -> 1107585 | T6: =IF(Payroll_Data_Analysis[[#This Row],[Base Salary (Monthly)]]>=200000,69507,IF(Payroll_Data_Analysis[[#This Row],[Base Salary (Monthly)]]>=145000,52684,35103)) -> 69507 | U6: =Payroll_Data_Analysis[[#This Row],[Annual KPI Bonus Reserve]]+Payroll_Data_Analysis[[#This Row],[Vacation Reserve]]+Payroll_Data_Analysis[[#This Row],[11-Month Salary]] -> 5767385.7 | V6: =Payroll_Data_Analysis[[#This Row],[Payroll Taxes (KPI Bonus)]]+Payroll_Data_Analysis[[#This Row],[Payroll Taxes (Vacation)]]+Payroll_Data_Analysis[[#This Row],[Payroll Taxes (Salary)]] -> 1533823.5 | W6: =Payroll_Data_Analysis[[#This Row],[Total Payroll]]+Payroll_Data_Analysis[[#This Row],[Total Payroll Taxes]] -> 7301209.1
A7: Administration | B7: Emp_006 | C7: Advisor to the First Deputy CEO – Department Director | D7: =VLOOKUP(Payroll_Data_Analysis[[#This Row],[Position]],Position_Map!$A$2:$B$58,2,FALSE) -> Professional | E7: 1 | F7: 336000 | G7: 200000 | I7: =dataset!$F7-dataset!$J7-dataset!$G7-dataset!$H7 -> 120000 | J7: =dataset!$G7*0.08 -> 16000 | K7: =dataset!$F7*12 -> 4032000 | L7: =IF(dataset!$G7>=200000,38%,IF(dataset!$G7<=145000,12.3%,)) -> 0.38 | M7: =dataset!$G7*L8*12 -> 295200 | N7: =IF(Payroll_Data_Analysis[[#This Row],[Annual KPI Bonus Reserve]]<=2979000,Payroll_Data_Analysis[[#This Row],[Annual KPI Bonus Reserve]]*0.302,2979000*0.302+(Payroll_Data_Analysis[[#This Row],[Annual KPI Bonus Reserve]]-2979000)*0.151) -> 89150.4 | O7: =dataset!$K7+dataset!$M7 -> 4327200 | P7: =Payroll_Data_Analysis[[#This Row],[Annual Salary + KPI Bonus]]/12/29.3*31 -> 381522.18 | Q7: =IF(Payroll_Data_Analysis[[#This Row],[Vacation Reserve]]<=2979000,Payroll_Data_Analysis[[#This Row],[Vacation Reserve]]*0.302,2979000*0.302+(Payroll_Data_Analysis[[#This Row],[Vacation Reserve]]-2979000)*0.151) -> 115219.7 | R7: =Payroll_Data_Analysis[[#This Row],[Monthly Salary]]*11 -> 3696000 | S7: =IF(Payroll_Data_Analysis[[#This Row],[11-Month Salary]]<=2979000,Payroll_Data_Analysis[[#This Row],[11-Month Salary]]*0.302,2979000*0.302+(Payroll_Data_Analysis[[#This Row],[11-Month Salary]]-2979000)*0.151) -> 1007925 | T7: =IF(Payroll_Data_Analysis[[#This Row],[Base Salary (Monthly)]]>=200000,69507,IF(Payroll_Data_Analysis[[#This Row],[Base Salary (Monthly)]]>=145000,52684,35103)) -> 69507 | U7: =Payroll_Data_Analysis[[#This Row],[Annual KPI Bonus Reserve]]+Payroll_Data_Analysis[[#This Row],[Vacation Reserve]]+Payroll_Data_Analysis[[#This Row],[11-Month Salary]] -> 4372722.2 | V7: =Payroll_Data_Analysis[[#This Row],[Payroll Taxes (KPI Bonus)]]+Payroll_Data_Analysis[[#This Row],[Payroll Taxes (Vacation)]]+Payroll_Data_Analysis[[#This Row],[Payroll Taxes (Salary)]] -> 1212295.1 | W7: =Payroll_Data_Analysis[[#This Row],[Total Payroll]]+Payroll_Data_Analysis[[#This Row],[Total Payroll Taxes]] -> 5585017.3
A8: Administration | B8: Emp_007 | C8: Department Director Assistant | D8: =VLOOKUP(Payroll_Data_Analysis[[#This Row],[Position]],Position_Map!$A$2:$B$58,2,FALSE) -> Administration | E8: 1 | F8: 281000 | G8: 145000 | I8: =dataset!$F8-dataset!$J8-dataset!$G8-dataset!$H8 -> 124400 | J8: =dataset!$G8*0.08 -> 11600 | K8: =dataset!$F8*12 -> 3372000 | L8: =IF(dataset!$G8>=200000,38%,IF(dataset!$G8<=145000,12.3%,)) -> 0.123 | M8: =dataset!$G8*L9*12 -> 214020 | N8: =IF(Payroll_Data_Analysis[[#This Row],[Annual KPI Bonus Reserve]]<=2979000,Payroll_Data_Analysis[[#This Row],[Annual KPI Bonus Reserve]]*0.302,2979000*0.302+(Payroll_Data_Analysis[[#This Row],[Annual KPI Bonus Reserve]]-2979000)*0.151) -> 64634.04 | O8: =dataset!$K8+dataset!$M8 -> 3586020 | P8: =Payroll_Data_Analysis[[#This Row],[Annual Salary + KPI Bonus]]/12/29.3*31 -> 316173.55 | Q8: =IF(Payroll_Data_Analysis[[#This Row],[Vacation Reserve]]<=2979000,Payroll_Data_Analysis[[#This Row],[Vacation Reserve]]*0.302,2979000*0.302+(Payroll_Data_Analysis[[#This Row],[Vacation Reserve]]-2979000)*0.151) -> 95484.412 | R8: =Payroll_Data_Analysis[[#This Row],[Monthly Salary]]*11 -> 3091000 | S8: =IF(Payroll_Data_Analysis[[#This Row],[11-Month Salary]]<=2979000,Payroll_Data_Analysis[[#This Row],[11-Month Salary]]*0.302,2979000*0.302+(Payroll_Data_Analysis[[#This Row],[11-Month Salary]]-2979000)*0.151) -> 916570 | T8: =IF(Payroll_Data_Analysis[[#This Row],[Base Salary (Monthly)]]>=200000,69507,IF(Payroll_Data_Analysis[[#This Row],[Base Salary (Monthly)]]>=145000,52684,35103)) -> 52684 | U8: =Payroll_Data_Analysis[[#This Row],[Annual KPI Bonus Reserve]]+Payroll_Data_Analysis[[#This Row],[Vacation Reserve]]+Payroll_Data_Analysis[[#This Row],[11-Month Salary]] -> 3621193.5 | V8: =Payroll_Data_Analysis[[#This Row],[Payroll Taxes (KPI Bonus)]]+Payroll_Data_Analysis[[#This Row],[Payroll Taxes (Vacation)]]+Payroll_Data_Analysis[[#This Row],[Payroll Taxes (Salary)]] -> 1076688.5 | W8: =Payroll_Data_Analysis[[#This Row],[Total Payroll]]+Payroll_Data_Analysis[[#This Row],[Total Payroll Taxes]] -> 4697882
A9: Administration | B9: Emp_008 | C9: Assistant | D9: =VLOOKUP(Payroll_Data_Analysis[[#This Row],[Position]],Position_Map!$A$2:$B$58,2,FALSE) -> Administration | E9: 1 | F9: 231600 | G9: 145000 | I9: =dataset!$F9-dataset!$J9-dataset!$G9-dataset!$H9 -> 75000 | J9: =dataset!$G9*0.08 -> 11600 | K9: =dataset!$F9*12 -> 2779200 | L9: =IF(dataset!$G9>=200000,38%,IF(dataset!$G9<=145000,12.3%,)) -> 0.123 | M9: =dataset!$G9*L10*12 -> 214020 | N9: =IF(Payroll_Data_Analysis[[#This Row],[Annual KPI Bonus Reserve]]<=2979000,Payroll_Data_Analysis[[#This Row],[Annual KPI Bonus Reserve]]*0.302,2979000*0.302+(Payroll_Data_Analysis[[#This Row],[Annual KPI Bonus Reserve]]-2979000)*0.151) -> 64634.04 | O9: =dataset!$K9+dataset!$M9 -> 2993220 | P9: =Payroll_Data_Analysis[[#This Row],[Annual Salary + KPI Bonus]]/12/29.3*31 -> 263907.34 | Q9: =IF(Payroll_Data_Analysis[[#This Row],[Vacation Reserve]]<=2979000,Payroll_Data_Analysis[[#This Row],[Vacation Reserve]]*0.302,2979000*0.302+(Payroll_Data_Analysis[[#This Row],[Vacation Reserve]]-2979000)*0.151) -> 79700.016 | R9: =Payroll_Data_Analysis[[#This Row],[Monthly Salary]]*11 -> 2547600 | S9: =IF(Payroll_Data_Analysis[[#This Row],[11-Month Salary]]<=2979000,Payroll_Data_Analysis[[#This Row],[11-Month Salary]]*0.302,2979000*0.302+(Payroll_Data_Analysis[[#This Row],[11-Month Salary]]-2979000)*0.151) -> 769375.2 | T9: =IF(Payroll_Data_Analysis[[#This Row],[Base Salary (Monthly)]]>=200000,69507,IF(Payroll_Data_Analysis[[#This Row],[Base Salary (Monthly)]]>=145000,52684,35103)) -> 52684 | U9: =Payroll_Data_Analysis[[#This Row],[Annual KPI Bonus Reserve]]+Payroll_Data_Analysis[[#This Row],[Vacation Reserve]]+Payroll_Data_Analysis[[#This Row],[11-Month Salary]] -> 3025527.3 | V9: =Payroll_Data_Analysis[[#This Row],[Payroll Taxes (KPI Bonus)]]+Payroll_Data_Analysis[[#This Row],[Payroll Taxes (Vacation)]]+Payroll_Data_Analysis[[#This Row],[Payroll Taxes (Salary)]] -> 913709.26 | W9: =Payroll_Data_Analysis[[#This Row],[Total Payroll]]+Payroll_Data_Analysis[[#This Row],[Total Payroll Taxes]] -> 3939236.6
A10: Pricing & Accounting | B10: Emp_009 | C10: Department Manager | D10: =VLOOKUP(Payroll_Data_Analysis[[#This Row],[Position]],Position_Map!$A$2:$B$58,2,FALSE) -> Management | E10: 1 | F10: 286000 | G10: 145000 | I10: =dataset!$F10-dataset!$J10-dataset!$G10-dataset!$H10 -> 129400 | J10: =dataset!$G10*0.08 -> 11600 | K10: =dataset!$F10*12 -> 3432000 | L10: =IF(dataset!$G10>=200000,38%,IF(dataset!$G10<=145000,12.3%,)) -> 0.123 | M10: =dataset!$G10*L11*12 -> 214020 | N10: =IF(Payroll_Data_Analysis[[#This Row],[Annual KPI Bonus Reserve]]<=2979000,Payroll_Data_Analysis[[#This Row],[Annual KPI Bonus Reserve]]*0.302,2979000*0.302+(Payroll_Data_Analysis[[#This Row],[Annual KPI Bonus Reserve]]-2979000)*0.151) -> 64634.04 | O10: =dataset!$K10+dataset!$M10 -> 3646020 | P10: =Payroll_Data_Analysis[[#This Row],[Annual Salary + KPI Bonus]]/12/29.3*31 -> 321463.65 | Q10: =IF(Payroll_Data_Analysis[[#This Row],[Vacation Reserve]]<=2979000,Payroll_Data_Analysis[[#This Row],[Vacation Reserve]]*0.302,2979000*0.302+(Payroll_Data_Analysis[[#This Row],[Vacation Reserve]]-2979000)*0.151) -> 97082.023 | R10: =Payroll_Data_Analysis[[#This Row],[Monthly Salary]]*11 -> 3146000 | S10: =IF(Payroll_Data_Analysis[[#This Row],[11-Month Salary]]<=2979000,Payroll_Data_Analysis[[#This Row],[11-Month Salary]]*0.302,2979000*0.302+(Payroll_Data_Analysis[[#This Row],[11-Month Salary]]-2979000)*0.151) -> 924875 | T10: =IF(Payroll_Data_Analysis[[#This Row],[Base Salary (Monthly)]]>=200000,69507,IF(Payroll_Data_Analysis[[#This Row],[Base Salary (Monthly)]]>=145000,52684,35103)) -> 52684 | U10: =Payroll_Data_Analysis[[#This Row],[Annual KPI Bonus Reserve]]+Payroll_Data_Analysis[[#This Row],[Vacation Reserve]]+Payroll_Data_Analysis[[#This Row],[11-Month Salary]] -> 3681483.7 | V10: =Payroll_Data_Analysis[[#This Row],[Payroll Taxes (KPI Bonus)]]+Payroll_Data_Analysis[[#This Row],[Payroll Taxes (Vacation)]]+Payroll_Data_Analysis[[#This Row],[Payroll Taxes (Salary)]] -> 1086591.1 | W10: =Payroll_Data_Analysis[[#This Row],[Total Payroll]]+Payroll_Data_Analysis[[#This Row],[Total Payroll Taxes]] -> 4768074.7
A11: Pricing & Accounting | B11: Emp_010 | C11: Deputy Department Manager | D11: =VLOOKUP(Payroll_Data_Analysis[[#This Row],[Position]],Position_Map!$A$2:$B$58,2,FALSE) -> Management | E11: 1 | F11: 186600 | G11: 145000 | I11: =dataset!$F11-dataset!$J11-dataset!$G11-dataset!$H11 -> 30000 | J11: =dataset!$G11*0.08 -> 11600 | K11: =dataset!$F11*12 -> 2239200 | L11: =IF(dataset!$G11>=200000,38%,IF(dataset!$G11<=145000,12.3%,)) -> 0.123 | M11: =dataset!$G11*L12*12 -> 214020 | N11: =IF(Payroll_Data_Analysis[[#This Row],[Annual KPI Bonus Reserve]]<=2979000,Payroll_Data_Analysis[[#This Row],[Annual KPI Bonus Reserve]]*0.302,2979000*0.302+(Payroll_Data_Analysis[[#This Row],[Annual KPI Bonus Reserve]]-2979000)*0.151) -> 64634.04 | O11: =dataset!$K11+dataset!$M11 -> 2453220 | P11: =Payroll_Data_Analysis[[#This Row],[Annual Salary + KPI Bonus]]/12/29.3*31 -> 216296.42 | Q11: =IF(Payroll_Data_Analysis[[#This Row],[Vacation Reserve]]<=2979000,Payroll_Data_Analysis[[#This Row],[Vacation Reserve]]*0.302,2979000*0.302+(Payroll_Data_Analysis[[#This Row],[Vacation Reserve]]-2979000)*0.151) -> 65321.518 | R11: =Payroll_Data_Analysis[[#This Row],[Monthly Salary]]*11 -> 2052600 | S11: =IF(Payroll_Data_Analysis[[#This Row],[11-Month Salary]]<=2979000,Payroll_Data_Analysis[[#This Row],[11-Month Salary]]*0.302,2979000*0.302+(Payroll_Data_Analysis[[#This Row],[11-Month Salary]]-2979000)*0.151) -> 619885.2 | T11: =IF(Payroll_Data_Analysis[[#This Row],[Base Salary (Monthly)]]>=200000,69507,IF(Payroll_Data_Analysis[[#This Row],[Base Salary (Monthly)]]>=145000,52684,35103)) -> 52684 | U11: =Payroll_Data_Analysis[[#This Row],[Annual KPI Bonus Reserve]]+Payroll_Data_Analysis[[#This Row],[Vacation Reserve]]+Payroll_Data_Analysis[[#This Row],[11-Month Salary]] -> 2482916.4 | V11: =Payroll_Data_Analysis[[#This Row],[Payroll Taxes (KPI Bonus)]]+Payroll_Data_Analysis[[#This Row],[Payroll Taxes (Vacation)]]+Payroll_Data_Analysis[[#This Row],[Payroll Taxes (Salary)]] -> 749840.76 | W11: =Payroll_Data_Analysis[[#This Row],[Total Payroll]]+Payroll_Data_Analysis[[#This Row],[Total Payroll Taxes]] -> 3232757.2
A12: Pricing & Accounting | B12: Emp_011 | C12: Deputy Department Manager | D12: =VLOOKUP(Payroll_Data_Analysis[[#This Row],[Position]],Position_Map!$A$2:$B$58,2,FALSE) -> Management | E12: 1 | F12: 158000 | G12: 100000 | I12: =dataset!$F12-dataset!$J12-dataset!$G12-dataset!$H12 -> 50000 | J12: =dataset!$G12*0.08 -> 8000 | K12: =dataset!$F12*12 -> 1896000 | L12: =IF(dataset!$G12>=200000,38%,IF(dataset!$G12<=145000,12.3%,)) -> 0.123 | M12: =dataset!$G12*L13*12 -> 147600 | N12: =IF(Payroll_Data_Analysis[[#This Row],[Annual KPI Bonus Reserve]]<=2979000,Payroll_Data_Analysis[[#This Row],[Annual KPI Bonus Reserve]]*0.302,2979000*0.302+(Payroll_Data_Analysis[[#This Row],[Annual KPI Bonus Reserve]]-2979000)*0.151) -> 44575.2 | O12: =dataset!$K12+dataset!$M12 -> 2043600 | P12: =Payroll_Data_Analysis[[#This Row],[Annual Salary + KPI Bonus]]/12/29.3*31 -> 180180.89 | Q12: =IF(Payroll_Data_Analysis[[#This Row],[Vacation Reserve]]<=2979000,Payroll_Data_Analysis[[#This Row],[Vacation Reserve]]*0.302,2979000*0.302+(Payroll_Data_Analysis[[#This Row],[Vacation Reserve]]-2979000)*0.151) -> 54414.628 | R12: =Payroll_Data_Analysis[[#This Row],[Monthly Salary]]*11 -> 1738000 | S12: =IF(Payroll_Data_Analysis[[#This Row],[11-Month Salary]]<=2979000,Payroll_Data_Analysis[[#This Row],[11-Month Salary]]*0.302,2979000*0.302+(Payroll_Data_Analysis[[#This Row],[11-Month Salary]]-2979000)*0.151) -> 524876 | T12: =IF(Payroll_Data_Analysis[[#This Row],[Base Salary (Monthly)]]>=200000,69507,IF(Payroll_Data_Analysis[[#This Row],[Base Salary (Monthly)]]>=145000,52684,35103)) -> 35103 | U12: =Payroll_Data_Analysis[[#This Row],[Annual KPI Bonus Reserve]]+Payroll_Data_Analysis[[#This Row],[Vacation Reserve]]+Payroll_Data_Analysis[[#This Row],[11-Month Salary]] -> 2065780.9 | V12: =Payroll_Data_Analysis[[#This Row],[Payroll Taxes (KPI Bonus)]]+Payroll_Data_Analysis[[#This Row],[Payroll Taxes (Vacation)]]+Payroll_Data_Analysis[[#This Row],[Payroll Taxes (Salary)]] -> 623865.83 | W12: =Payroll_Data_Analysis[[#This Row],[Total Payroll]]+Payroll_Data_Analysis[[#This Row],[Total Payroll Taxes]] -> 2689646.7
A13: Pricing & Accounting | B13: Emp_012 | C13: Senior Specialist | D13: =VLOOKUP(Payroll_Data_Analysis[[#This Row],[Position]],Position_Map!$A$2:$B$58,2,FALSE) -> Professional | E13: 1 | F13: 94800 | G13: 60000 | I13: =dataset!$F13-dataset!$J13-dataset!$G13-dataset!$H13 -> 30000 | J13: =dataset!$G13*0.08 -> 4800 | K13: =dataset!$F13*12 -> 1137600 | L13: =IF(dataset!$G13>=200000,38%,IF(dataset!$G13<=145000,12.3%,)) -> 0.123 | M13: =dataset!$G13*L14*12 -> 88560 | N13: =IF(Payroll_Data_Analysis[[#This Row],[Annual KPI Bonus Reserve]]<=2979000,Payroll_Data_Analysis[[#This Row],[Annual KPI Bonus Reserve]]*0.302,2979000*0.302+(Payroll_Data_Analysis[[#This Row],[Annual KPI Bonus Reserve]]-2979000)*0.151) -> 26745.12 | O13: =dataset!$K13+dataset!$M13 -> 1226160 | P13: =Payroll_Data_Analysis[[#This Row],[Annual Salary + KPI Bonus]]/12/29.3*31 -> 108108.53 | Q13: =IF(Payroll_Data_Analysis[[#This Row],[Vacation Reserve]]<=2979000,Payroll_Data_Analysis[[#This Row],[Vacation Reserve]]*0.302,2979000*0.302+(Payroll_Data_Analysis[[#This Row],[Vacation Reserve]]-2979000)*0.151) -> 32648.777 | R13: =Payroll_Data_Analysis[[#This Row],[Monthly Salary]]*11 -> 1042800 | S13: =IF(Payroll_Data_Analysis[[#This Row],[11-Month Salary]]<=2979000,Payroll_Data_Analysis[[#This Row],[11-Month Salary]]*0.302,2979000*0.302+(Payroll_Data_Analysis[[#This Row],[11-Month Salary]]-2979000)*0.151) -> 314925.6 | T13: =IF(Payroll_Data_Analysis[[#This Row],[Base Salary (Monthly)]]>=200000,69507,IF(Payroll_Data_Analysis[[#This Row],[Base Salary (Monthly)]]>=145000,52684,35103)) -> 35103 | U13: =Payroll_Data_Analysis[[#This Row],[Annual KPI Bonus Reserve]]+Payroll_Data_Analysis[[#This Row],[Vacation Reserve]]+Payroll_Data_Analysis[[#This Row],[11-Month Salary]] -> 1239468.5 | V13: =Payroll_Data_Analysis[[#This Row],[Payroll Taxes (KPI Bonus)]]+Payroll_Data_Analysis[[#This Row],[Payroll Taxes (Vacation)]]+Payroll_Data_Analysis[[#This Row],[Payroll Taxes (Salary)]] -> 374319.5 | W13: =Payroll_Data_Analysis[[#This Row],[Total Payroll]]+Payroll_Data_Analysis[[#This Row],[Total Payroll Taxes]] -> 1613788
A14: Pricing & Accounting | B14: Emp_013 | C14: Senior Specialist | D14: =VLOOKUP(Payroll_Data_Analysis[[#This Row],[Position]],Position_Map!$A$2:$B$58,2,FALSE) -> Professional | E14: 1 | F14: 74000 | G14: 50000 | I14: =dataset!$F14-dataset!$J14-dataset!$G14-dataset!$H14 -> 20000 | J14: =dataset!$G14*0.08 -> 4000 | K14: =dataset!$F14*12 -> 888000 | L14: =IF(dataset!$G14>=200000,38%,IF(dataset!$G14<=145000,12.3%,)) -> 0.123 | M14: =dataset!$G14*L15*12 -> 73800 | N14: =IF(Payroll_Data_Analysis[[#This Row],[Annual KPI Bonus Reserve]]<=2979000,Payroll_Data_Analysis[[#This Row],[Annual KPI Bonus Reserve]]*0.302,2979000*0.302+(Payroll_Data_Analysis[[#This Row],[Annual KPI Bonus Reserve]]-2979000)*0.151) -> 22287.6 | O14: =dataset!$K14+dataset!$M14 -> 961800 | P14: =Payroll_Data_Analysis[[#This Row],[Annual Salary + KPI Bonus]]/12/29.3*31 -> 84800.341 | Q14: =IF(Payroll_Data_Analysis[[#This Row],[Vacation Reserve]]<=2979000,Payroll_Data_Analysis[[#This Row],[Vacation Reserve]]*0.302,2979000*0.302+(Payroll_Data_Analysis[[#This Row],[Vacation Reserve]]-2979000)*0.151) -> 25609.703 | R14: =Payroll_Data_Analysis[[#This Row],[Monthly Salary]]*11 -> 814000 | S14: =IF(Payroll_Data_Analysis[[#This Row],[11-Month Salary]]<=2979000,Payroll_Data_Analysis[[#This Row],[11-Month Salary]]*0.302,2979000*0.302+(Payroll_Data_Analysis[[#This Row],[11-Month Salary]]-2979000)*0.151) -> 245828 | T14: =IF(Payroll_Data_Analysis[[#This Row],[Base Salary (Monthly)]]>=200000,69507,IF(Payroll_Data_Analysis[[#This Row],[Base Salary (Monthly)]]>=145000,52684,35103)) -> 35103 | U14: =Payroll_Data_Analysis[[#This Row],[Annual KPI Bonus Reserve]]+Payroll_Data_Analysis[[#This Row],[Vacation Reserve]]+Payroll_Data_Analysis[[#This Row],[11-Month Salary]] -> 972600.34 | V14: =Payroll_Data_Analysis[[#This Row],[Payroll Taxes (KPI Bonus)]]+Payroll_Data_Analysis[[#This Row],[Payroll Taxes (Vacation)]]+Payroll_Data_Analysis[[#This Row],[Payroll Taxes (Salary)]] -> 293725.3 | W14: =Payroll_Data_Analysis[[#This Row],[Total Payroll]]+Payroll_Data_Analysis[[#This Row],[Total Payroll Taxes]] -> 1266325.6
... A95: Engineering | B95: Emp_094 | C95: Senior Engineer | D95: =VLOOKUP(Payroll_Data_Analysis[[#This Row],[Position]],Position_Map!$A$2:$B$58,2,FALSE) -> Engineering | E95: 1 | F95: 158000 | G95: 100000 | I95: =dataset!$F95-dataset!$J95-dataset!$G95-dataset!$H95 -> 50000 | J95: =dataset!$G95*0.08 -> 8000 | K95: =dataset!$F95*12 -> 1896000 | L95: =IF(dataset!$G95>=200000,38%,IF(dataset!$G95<=145000,12.3%,)) -> 0.123 | M95: =dataset!$G95*L96*12 -> 456000 | N95: =IF(Payroll_Data_Analysis[[#This Row],[Annual KPI Bonus Reserve]]<=2979000,Payroll_Data_Analysis[[#This Row],[Annual KPI Bonus Reserve]]*0.302,2979000*0.302+(Payroll_Data_Analysis[[#This Row],[Annual KPI Bonus Reserve]]-2979000)*0.151) -> 137712 | O95: =dataset!$K95+dataset!$M95 -> 2352000 | P95: =Payroll_Data_Analysis[[#This Row],[Annual Salary + KPI Bonus]]/12/29.3*31 -> 207372.01 | Q95: =IF(Payroll_Data_Analysis[[#This Row],[Vacation Reserve]]<=2979000,Payroll_Data_Analysis[[#This Row],[Vacation Reserve]]*0.302,2979000*0.302+(Payroll_Data_Analysis[[#This Row],[Vacation Reserve]]-2979000)*0.151) -> 62626.348 | R95: =Payroll_Data_Analysis[[#This Row],[Monthly Salary]]*11 -> 1738000 | S95: =IF(Payroll_Data_Analysis[[#This Row],[11-Month Salary]]<=2979000,Payroll_Data_Analysis[[#This Row],[11-Month Salary]]*0.302,2979000*0.302+(Payroll_Data_Analysis[[#This Row],[11-Month Salary]]-2979000)*0.151) -> 524876 | T95: =IF(Payroll_Data_Analysis[[#This Row],[Base Salary (Monthly)]]>=200000,69507,IF(Payroll_Data_Analysis[[#This Row],[Base Salary (Monthly)]]>=145000,52684,35103)) -> 35103 | U95: =Payroll_Data_Analysis[[#This Row],[Annual KPI Bonus Reserve]]+Payroll_Data_Analysis[[#This Row],[Vacation Reserve]]+Payroll_Data_Analysis[[#This Row],[11-Month Salary]] -> 2401372 | V95: =Payroll_Data_Analysis[[#This Row],[Payroll Taxes (KPI Bonus)]]+Payroll_Data_Analysis[[#This Row],[Payroll Taxes (Vacation)]]+Payroll_Data_Analysis[[#This Row],[Payroll Taxes (Salary)]] -> 725214.35 | W95: =Payroll_Data_Analysis[[#This Row],[Total Payroll]]+Payroll_Data_Analysis[[#This Row],[Total Payroll Taxes]] -> 3126586.4
A96: Engineering | B96: Emp_095 | C96: Deputy CEO – Department Manager | D96: =VLOOKUP(Payroll_Data_Analysis[[#This Row],[Position]],Position_Map!$A$2:$B$58,2,FALSE) -> Executive | E96: 1 | F96: 396000 | G96: 200000 | H96: 20000 | I96: =dataset!$F96-dataset!$J96-dataset!$G96-dataset!$H96 -> 160000 | J96: =dataset!$G96*0.08 -> 16000 | K96: =dataset!$F96*12 -> 4752000 | L96: =IF(dataset!$G96>=200000,38%,IF(dataset!$G96<=145000,12.3%,)) -> 0.38 | M96: =dataset!$G96*L97*12 -> 295200 | N96: =IF(Payroll_Data_Analysis[[#This Row],[Annual KPI Bonus Reserve]]<=2979000,Payroll_Data_Analysis[[#This Row],[Annual KPI Bonus Reserve]]*0.302,2979000*0.302+(Payroll_Data_Analysis[[#This Row],[Annual KPI Bonus Reserve]]-2979000)*0.151) -> 89150.4 | O96: =dataset!$K96+dataset!$M96 -> 5047200 | P96: =Payroll_Data_Analysis[[#This Row],[Annual Salary + KPI Bonus]]/12/29.3*31 -> 445003.41 | Q96: =IF(Payroll_Data_Analysis[[#This Row],[Vacation Reserve]]<=2979000,Payroll_Data_Analysis[[#This Row],[Vacation Reserve]]*0.302,2979000*0.302+(Payroll_Data_Analysis[[#This Row],[Vacation Reserve]]-2979000)*0.151) -> 134391.03 | R96: =Payroll_Data_Analysis[[#This Row],[Monthly Salary]]*11 -> 4356000 | S96: =IF(Payroll_Data_Analysis[[#This Row],[11-Month Salary]]<=2979000,Payroll_Data_Analysis[[#This Row],[11-Month Salary]]*0.302,2979000*0.302+(Payroll_Data_Analysis[[#This Row],[11-Month Salary]]-2979000)*0.151) -> 1107585 | T96: =IF(Payroll_Data_Analysis[[#This Row],[Base Salary (Monthly)]]>=200000,69507,IF(Payroll_Data_Analysis[[#This Row],[Base Salary (Monthly)]]>=145000,52684,35103)) -> 69507 | U96: =Payroll_Data_Analysis[[#This Row],[Annual KPI Bonus Reserve]]+Payroll_Data_Analysis[[#This Row],[Vacation Reserve]]+Payroll_Data_Analysis[[#This Row],[11-Month Salary]] -> 5096203.4 | V96: =Payroll_Data_Analysis[[#This Row],[Payroll Taxes (KPI Bonus)]]+Payroll_Data_Analysis[[#This Row],[Payroll Taxes (Vacation)]]+Payroll_Data_Analysis[[#This Row],[Payroll Taxes (Salary)]] -> 1331126.4 | W96: =Payroll_Data_Analysis[[#This Row],[Total Payroll]]+Payroll_Data_Analysis[[#This Row],[Total Payroll Taxes]] -> 6427329.8
A97: Economic Security | B97: Emp_096 | C97: Deputy Department Manager | D97: =VLOOKUP(Payroll_Data_Analysis[[#This Row],[Position]],Position_Map!$A$2:$B$58,2,FALSE) -> Management | E97: 1 | F97: 211600 | G97: 145000 | I97: =dataset!$F97-dataset!$J97-dataset!$G97-dataset!$H97 -> 55000 | J97: =dataset!$G97*0.08 -> 11600 | K97: =dataset!$F97*12 -> 2539200 | L97: =IF(dataset!$G97>=200000,38%,IF(dataset!$G97<=145000,12.3%,)) -> 0.123 | M97: =dataset!$G97*L98*12 -> 214020 | N97: =IF(Payroll_Data_Analysis[[#This Row],[Annual KPI Bonus Reserve]]<=2979000,Payroll_Data_Analysis[[#This Row],[Annual KPI Bonus Reserve]]*0.302,2979000*0.302+(Payroll_Data_Analysis[[#This Row],[Annual KPI Bonus Reserve]]-2979000)*0.151) -> 64634.04 | O97: =dataset!$K97+dataset!$M97 -> 2753220 | P97: =Payroll_Data_Analysis[[#This Row],[Annual Salary + KPI Bonus]]/12/29.3*31 -> 242746.93 | Q97: =IF(Payroll_Data_Analysis[[#This Row],[Vacation Reserve]]<=2979000,Payroll_Data_Analysis[[#This Row],[Vacation Reserve]]*0.302,2979000*0.302+(Payroll_Data_Analysis[[#This Row],[Vacation Reserve]]-2979000)*0.151) -> 73309.572 | R97: =Payroll_Data_Analysis[[#This Row],[Monthly Salary]]*11 -> 2327600 | S97: =IF(Payroll_Data_Analysis[[#This Row],[11-Month Salary]]<=2979000,Payroll_Data_Analysis[[#This Row],[11-Month Salary]]*0.302,2979000*0.302+(Payroll_Data_Analysis[[#This Row],[11-Month Salary]]-2979000)*0.151) -> 702935.2 | T97: =IF(Payroll_Data_Analysis[[#This Row],[Base Salary (Monthly)]]>=200000,69507,IF(Payroll_Data_Analysis[[#This Row],[Base Salary (Monthly)]]>=145000,52684,35103)) -> 52684 | U97: =Payroll_Data_Analysis[[#This Row],[Annual KPI Bonus Reserve]]+Payroll_Data_Analysis[[#This Row],[Vacation Reserve]]+Payroll_Data_Analysis[[#This Row],[11-Month Salary]] -> 2784366.9 | V97: =Payroll_Data_Analysis[[#This Row],[Payroll Taxes (KPI Bonus)]]+Payroll_Data_Analysis[[#This Row],[Payroll Taxes (Vacation)]]+Payroll_Data_Analysis[[#This Row],[Payroll Taxes (Salary)]] -> 840878.81 | W97: =Payroll_Data_Analysis[[#This Row],[Total Payroll]]+Payroll_Data_Analysis[[#This Row],[Total Payroll Taxes]] -> 3625245.7
A98: Economic Security | B98: Emp_097 | C98: Lead Specialist | D98: =VLOOKUP(Payroll_Data_Analysis[[#This Row],[Position]],Position_Map!$A$2:$B$58,2,FALSE) -> Professional | E98: 1 | F98: 138000 | G98: 100000 | I98: =dataset!$F98-dataset!$J98-dataset!$G98-dataset!$H98 -> 30000 | J98: =dataset!$G98*0.08 -> 8000 | K98: =dataset!$F98*12 -> 1656000 | L98: =IF(dataset!$G98>=200000,38%,IF(dataset!$G98<=145000,12.3%,)) -> 0.123 | M98: =dataset!$G98*L99*12 -> 147600 | N98: =IF(Payroll_Data_Analysis[[#This Row],[Annual KPI Bonus Reserve]]<=2979000,Payroll_Data_Analysis[[#This Row],[Annual KPI Bonus Reserve]]*0.302,2979000*0.302+(Payroll_Data_Analysis[[#This Row],[Annual KPI Bonus Reserve]]-2979000)*0.151) -> 44575.2 | O98: =dataset!$K98+dataset!$M98 -> 1803600 | P98: =Payroll_Data_Analysis[[#This Row],[Annual Salary + KPI Bonus]]/12/29.3*31 -> 159020.48 | Q98: =IF(Payroll_Data_Analysis[[#This Row],[Vacation Reserve]]<=2979000,Payroll_Data_Analysis[[#This Row],[Vacation Reserve]]*0.302,2979000*0.302+(Payroll_Data_Analysis[[#This Row],[Vacation Reserve]]-2979000)*0.151) -> 48024.184 | R98: =Payroll_Data_Analysis[[#This Row],[Monthly Salary]]*11 -> 1518000 | S98: =IF(Payroll_Data_Analysis[[#This Row],[11-Month Salary]]<=2979000,Payroll_Data_Analysis[[#This Row],[11-Month Salary]]*0.302,2979000*0.302+(Payroll_Data_Analysis[[#This Row],[11-Month Salary]]-2979000)*0.151) -> 458436 | T98: =IF(Payroll_Data_Analysis[[#This Row],[Base Salary (Monthly)]]>=200000,69507,IF(Payroll_Data_Analysis[[#This Row],[Base Salary (Monthly)]]>=145000,52684,35103)) -> 35103 | U98: =Payroll_Data_Analysis[[#This Row],[Annual KPI Bonus Reserve]]+Payroll_Data_Analysis[[#This Row],[Vacation Reserve]]+Payroll_Data_Analysis[[#This Row],[11-Month Salary]] -> 1824620.5 | V98: =Payroll_Data_Analysis[[#This Row],[Payroll Taxes (KPI Bonus)]]+Payroll_Data_Analysis[[#This Row],[Payroll Taxes (Vacation)]]+Payroll_Data_Analysis[[#This Row],[Payroll Taxes (Salary)]] -> 551035.38 | W98: =Payroll_Data_Analysis[[#This Row],[Total Payroll]]+Payroll_Data_Analysis[[#This Row],[Total Payroll Taxes]] -> 2375655.9
A99: Economic Security | B99: Emp_098 | C99: Lead Specialist | D99: =VLOOKUP(Payroll_Data_Analysis[[#This Row],[Position]],Position_Map!$A$2:$B$58,2,FALSE) -> Professional | E99: 1 | F99: 211100 | G99: 145000 | I99: =dataset!$F99-dataset!$J99-dataset!$G99-dataset!$H99 -> 54500 | J99: =dataset!$G99*0.08 -> 11600 | K99: =dataset!$F99*12 -> 2533200 | L99: =IF(dataset!$G99>=200000,38%,IF(dataset!$G99<=145000,12.3%,)) -> 0.123 | M99: =dataset!$G99*L100*12 -> 214020 | N99: =IF(Payroll_Data_Analysis[[#This Row],[Annual KPI Bonus Reserve]]<=2979000,Payroll_Data_Analysis[[#This Row],[Annual KPI Bonus Reserve]]*0.302,2979000*0.302+(Payroll_Data_Analysis[[#This Row],[Annual KPI Bonus Reserve]]-2979000)*0.151) -> 64634.04 | O99: =dataset!$K99+dataset!$M99 -> 2747220 | P99: =Payroll_Data_Analysis[[#This Row],[Annual Salary + KPI Bonus]]/12/29.3*31 -> 242217.92 | Q99: =IF(Payroll_Data_Analysis[[#This Row],[Vacation Reserve]]<=2979000,Payroll_Data_Analysis[[#This Row],[Vacation Reserve]]*0.302,2979000*0.302+(Payroll_Data_Analysis[[#This Row],[Vacation Reserve]]-2979000)*0.151) -> 73149.811 | R99: =Payroll_Data_Analysis[[#This Row],[Monthly Salary]]*11 -> 2322100 | S99: =IF(Payroll_Data_Analysis[[#This Row],[11-Month Salary]]<=2979000,Payroll_Data_Analysis[[#This Row],[11-Month Salary]]*0.302,2979000*0.302+(Payroll_Data_Analysis[[#This Row],[11-Month Salary]]-2979000)*0.151) -> 701274.2 | T99: =IF(Payroll_Data_Analysis[[#This Row],[Base Salary (Monthly)]]>=200000,69507,IF(Payroll_Data_Analysis[[#This Row],[Base Salary (Monthly)]]>=145000,52684,35103)) -> 52684 | U99: =Payroll_Data_Analysis[[#This Row],[Annual KPI Bonus Reserve]]+Payroll_Data_Analysis[[#This Row],[Vacation Reserve]]+Payroll_Data_Analysis[[#This Row],[11-Month Salary]] -> 2778337.9 | V99: =Payroll_Data_Analysis[[#This Row],[Payroll Taxes (KPI Bonus)]]+Payroll_Data_Analysis[[#This Row],[Payroll Taxes (Vacation)]]+Payroll_Data_Analysis[[#This Row],[Payroll Taxes (Salary)]] -> 839058.05 | W99: =Payroll_Data_Analysis[[#This Row],[Total Payroll]]+Payroll_Data_Analysis[[#This Row],[Total Payroll Taxes]] -> 3617396
A100: Economic Security | B100: Emp_099 | C100: Lead Specialist | D100: =VLOOKUP(Payroll_Data_Analysis[[#This Row],[Position]],Position_Map!$A$2:$B$58,2,FALSE) -> Professional | E100: 1 | F100: 211100 | G100: 145000 | I100: =dataset!$F100-dataset!$J100-dataset!$G100-dataset!$H100 -> 54500 | J100: =dataset!$G100*0.08 -> 11600 | K100: =dataset!$F100*12 -> 2533200 | L100: =IF(dataset!$G100>=200000,38%,IF(dataset!$G100<=145000,12.3%,)) -> 0.123 | M100: =dataset!$G100*L101*12 -> 214020 | N100: =IF(Payroll_Data_Analysis[[#This Row],[Annual KPI Bonus Reserve]]<=2979000,Payroll_Data_Analysis[[#This Row],[Annual KPI Bonus Reserve]]*0.302,2979000*0.302+(Payroll_Data_Analysis[[#This Row],[Annual KPI Bonus Reserve]]-2979000)*0.151) -> 64634.04 | O100: =dataset!$K100+dataset!$M100 -> 2747220 | P100: =Payroll_Data_Analysis[[#This Row],[Annual Salary + KPI Bonus]]/12/29.3*31 -> 242217.92 | Q100: =IF(Payroll_Data_Analysis[[#This Row],[Vacation Reserve]]<=2979000,Payroll_Data_Analysis[[#This Row],[Vacation Reserve]]*0.302,2979000*0.302+(Payroll_Data_Analysis[[#This Row],[Vacation Reserve]]-2979000)*0.151) -> 73149.811 | R100: =Payroll_Data_Analysis[[#This Row],[Monthly Salary]]*11 -> 2322100 | S100: =IF(Payroll_Data_Analysis[[#This Row],[11-Month Salary]]<=2979000,Payroll_Data_Analysis[[#This Row],[11-Month Salary]]*0.302,2979000*0.302+(Payroll_Data_Analysis[[#This Row],[11-Month Salary]]-2979000)*0.151) -> 701274.2 | T100: =IF(Payroll_Data_Analysis[[#This Row],[Base Salary (Monthly)]]>=200000,69507,IF(Payroll_Data_Analysis[[#This Row],[Base Salary (Monthly)]]>=145000,52684,35103)) -> 52684 | U100: =Payroll_Data_Analysis[[#This Row],[Annual KPI Bonus Reserve]]+Payroll_Data_Analysis[[#This Row],[Vacation Reserve]]+Payroll_Data_Analysis[[#This Row],[11-Month Salary]] -> 2778337.9 | V100: =Payroll_Data_Analysis[[#This Row],[Payroll Taxes (KPI Bonus)]]+Payroll_Data_Analysis[[#This Row],[Payroll Taxes (Vacation)]]+Payroll_Data_Analysis[[#This Row],[Payroll Taxes (Salary)]] -> 839058.05 | W100: =Payroll_Data_Analysis[[#This Row],[Total Payroll]]+Payroll_Data_Analysis[[#This Row],[Total Payroll Taxes]] -> 3617396
A101: Economic Security | B101: Emp_100 | C101: Department Manager | D101: =VLOOKUP(Payroll_Data_Analysis[[#This Row],[Position]],Position_Map!$A$2:$B$58,2,FALSE) -> Management | E101: 1 | F101: 261600 | G101: 145000 | I101: =dataset!$F101-dataset!$J101-dataset!$G101-dataset!$H101 -> 105000 | J101: =dataset!$G101*0.08 -> 11600 | K101: =dataset!$F101*12 -> 3139200 | L101: =IF(dataset!$G101>=200000,38%,IF(dataset!$G101<=145000,12.3%,)) -> 0.123 | M101: =dataset!$G101*L102*12 -> 214020 | N101: =IF(Payroll_Data_Analysis[[#This Row],[Annual KPI Bonus Reserve]]<=2979000,Payroll_Data_Analysis[[#This Row],[Annual KPI Bonus Reserve]]*0.302,2979000*0.302+(Payroll_Data_Analysis[[#This Row],[Annual KPI Bonus Reserve]]-2979000)*0.151) -> 64634.04 | O101: =dataset!$K101+dataset!$M101 -> 3353220 | P101: =Payroll_Data_Analysis[[#This Row],[Annual Salary + KPI Bonus]]/12/29.3*31 -> 295647.95 | Q101: =IF(Payroll_Data_Analysis[[#This Row],[Vacation Reserve]]<=2979000,Payroll_Data_Analysis[[#This Row],[Vacation Reserve]]*0.302,2979000*0.302+(Payroll_Data_Analysis[[#This Row],[Vacation Reserve]]-2979000)*0.151) -> 89285.682 | R101: =Payroll_Data_Analysis[[#This Row],[Monthly Salary]]*11 -> 2877600 | S101: =IF(Payroll_Data_Analysis[[#This Row],[11-Month Salary]]<=2979000,Payroll_Data_Analysis[[#This Row],[11-Month Salary]]*0.302,2979000*0.302+(Payroll_Data_Analysis[[#This Row],[11-Month Salary]]-2979000)*0.151) -> 869035.2 | T101: =IF(Payroll_Data_Analysis[[#This Row],[Base Salary (Monthly)]]>=200000,69507,IF(Payroll_Data_Analysis[[#This Row],[Base Salary (Monthly)]]>=145000,52684,35103)) -> 52684 | U101: =Payroll_Data_Analysis[[#This Row],[Annual KPI Bonus Reserve]]+Payroll_Data_Analysis[[#This Row],[Vacation Reserve]]+Payroll_Data_Analysis[[#This Row],[11-Month Salary]] -> 3387268 | V101: =Payroll_Data_Analysis[[#This Row],[Payroll Taxes (KPI Bonus)]]+Payroll_Data_Analysis[[#This Row],[Payroll Taxes (Vacation)]]+Payroll_Data_Analysis[[#This Row],[Payroll Taxes (Salary)]] -> 1022954.9 | W101: =Payroll_Data_Analysis[[#This Row],[Total Payroll]]+Payroll_Data_Analysis[[#This Row],[Total Payroll Taxes]] -> 4410222.9
A102: Economic Security | B102: Emp_101 | C102: Lead Specialist | D102: =VLOOKUP(Payroll_Data_Analysis[[#This Row],[Position]],Position_Map!$A$2:$B$58,2,FALSE) -> Professional | E102: 1 | F102: 158000 | G102: 100000 | I102: =dataset!$F102-dataset!$J102-dataset!$G102-dataset!$H102 -> 50000 | J102: =dataset!$G102*0.08 -> 8000 | K102: =dataset!$F102*12 -> 1896000 | L102: =IF(dataset!$G102>=200000,38%,IF(dataset!$G102<=145000,12.3%,)) -> 0.123 | M102: =dataset!$G102*L103*12 -> 147600 | N102: =IF(Payroll_Data_Analysis[[#This Row],[Annual KPI Bonus Reserve]]<=2979000,Payroll_Data_Analysis[[#This Row],[Annual KPI Bonus Reserve]]*0.302,2979000*0.302+(Payroll_Data_Analysis[[#This Row],[Annual KPI Bonus Reserve]]-2979000)*0.151) -> 44575.2 | O102: =dataset!$K102+dataset!$M102 -> 2043600 | P102: =Payroll_Data_Analysis[[#This Row],[Annual Salary + KPI Bonus]]/12/29.3*31 -> 180180.89 | Q102: =IF(Payroll_Data_Analysis[[#This Row],[Vacation Reserve]]<=2979000,Payroll_Data_Analysis[[#This Row],[Vacation Reserve]]*0.302,2979000*0.302+(Payroll_Data_Analysis[[#This Row],[Vacation Reserve]]-2979000)*0.151) -> 54414.628 | R102: =Payroll_Data_Analysis[[#This Row],[Monthly Salary]]*11 -> 1738000 | S102: =IF(Payroll_Data_Analysis[[#This Row],[11-Month Salary]]<=2979000,Payroll_Data_Analysis[[#This Row],[11-Month Salary]]*0.302,2979000*0.302+(Payroll_Data_Analysis[[#This Row],[11-Month Salary]]-2979000)*0.151) -> 524876 | T102: =IF(Payroll_Data_Analysis[[#This Row],[Base Salary (Monthly)]]>=200000,69507,IF(Payroll_Data_Analysis[[#This Row],[Base Salary (Monthly)]]>=145000,52684,35103)) -> 35103 | U102: =Payroll_Data_Analysis[[#This Row],[Annual KPI Bonus Reserve]]+Payroll_Data_Analysis[[#This Row],[Vacation Reserve]]+Payroll_Data_Analysis[[#This Row],[11-Month Salary]] -> 2065780.9 | V102: =Payroll_Data_Analysis[[#This Row],[Payroll Taxes (KPI Bonus)]]+Payroll_Data_Analysis[[#This Row],[Payroll Taxes (Vacation)]]+Payroll_Data_Analysis[[#This Row],[Payroll Taxes (Salary)]] -> 623865.83 | W102: =Payroll_Data_Analysis[[#This Row],[Total Payroll]]+Payroll_Data_Analysis[[#This Row],[Total Payroll Taxes]] -> 2689646.7
A103: Economic Security | B103: Emp_102 | C103: Senior Specialist | D103: =VLOOKUP(Payroll_Data_Analysis[[#This Row],[Position]],Position_Map!$A$2:$B$58,2,FALSE) -> Professional | E103: 1 | F103: 126400 | G103: 80000 | I103: =dataset!$F103-dataset!$J103-dataset!$G103-dataset!$H103 -> 40000 | J103: =dataset!$G103*0.08 -> 6400 | K103: =dataset!$F103*12 -> 1516800 | L103: =IF(dataset!$G103>=200000,38%,IF(dataset!$G103<=145000,12.3%,)) -> 0.123 | M103: =dataset!$G103*L104*12 -> 118080 | N103: =IF(Payroll_Data_Analysis[[#This Row],[Annual KPI Bonus Reserve]]<=2979000,Payroll_Data_Analysis[[#This Row],[Annual KPI Bonus Reserve]]*0.302,2979000*0.302+(Payroll_Data_Analysis[[#This Row],[Annual KPI Bonus Reserve]]-2979000)*0.151) -> 35660.16 | O103: =dataset!$K103+dataset!$M103 -> 1634880 | P103: =Payroll_Data_Analysis[[#This Row],[Annual Salary + KPI Bonus]]/12/29.3*31 -> 144144.71 | Q103: =IF(Payroll_Data_Analysis[[#This Row],[Vacation Reserve]]<=2979000,Payroll_Data_Analysis[[#This Row],[Vacation Reserve]]*0.302,2979000*0.302+(Payroll_Data_Analysis[[#This Row],[Vacation Reserve]]-2979000)*0.151) -> 43531.702 | R103: =Payroll_Data_Analysis[[#This Row],[Monthly Salary]]*11 -> 1390400 | S103: =IF(Payroll_Data_Analysis[[#This Row],[11-Month Salary]]<=2979000,Payroll_Data_Analysis[[#This Row],[11-Month Salary]]*0.302,2979000*0.302+(Payroll_Data_Analysis[[#This Row],[11-Month Salary]]-2979000)*0.151) -> 419900.8 | T103: =IF(Payroll_Data_Analysis[[#This Row],[Base Salary (Monthly)]]>=200000,69507,IF(Payroll_Data_Analysis[[#This Row],[Base Salary (Monthly)]]>=145000,52684,35103)) -> 35103 | U103: =Payroll_Data_Analysis[[#This Row],[Annual KPI Bonus Reserve]]+Payroll_Data_Analysis[[#This Row],[Vacation Reserve]]+Payroll_Data_Analysis[[#This Row],[11-Month Salary]] -> 1652624.7 | V103: =Payroll_Data_Analysis[[#This Row],[Payroll Taxes (KPI Bonus)]]+Payroll_Data_Analysis[[#This Row],[Payroll Taxes (Vacation)]]+Payroll_Data_Analysis[[#This Row],[Payroll Taxes (Salary)]] -> 499092.66 | W103: =Payroll_Data_Analysis[[#This Row],[Total Payroll]]+Payroll_Data_Analysis[[#This Row],[Total Payroll Taxes]] -> 2151717.4
A104: Economic Security | B104: Emp_103 | C104: Senior Engineer | D104: =VLOOKUP(Payroll_Data_Analysis[[#This Row],[Position]],Position_Map!$A$2:$B$58,2,FALSE) -> Engineering | E104: 1 | F104: 173000 | G104: 100000 | I104: =dataset!$F104-dataset!$J104-dataset!$G104-dataset!$H104 -> 65000 | J104: =dataset!$G104*0.08 -> 8000 | K104: =dataset!$F104*12 -> 2076000 | L104: =IF(dataset!$G104>=200000,38%,IF(dataset!$G104<=145000,12.3%,)) -> 0.123 | M104: =dataset!$G104*L105*12 -> 147600 | N104: =IF(Payroll_Data_Analysis[[#This Row],[Annual KPI Bonus Reserve]]<=2979000,Payroll_Data_Analysis[[#This Row],[Annual KPI Bonus Reserve]]*0.302,2979000*0.302+(Payroll_Data_Analysis[[#This Row],[Annual KPI Bonus Reserve]]-2979000)*0.151) -> 44575.2 | O104: =dataset!$K104+dataset!$M104 -> 2223600 | P104: =Payroll_Data_Analysis[[#This Row],[Annual Salary + KPI Bonus]]/12/29.3*31 -> 196051.19 | Q104: =IF(Payroll_Data_Analysis[[#This Row],[Vacation Reserve]]<=2979000,Payroll_Data_Analysis[[#This Row],[Vacation Reserve]]*0.302,2979000*0.302+(Payroll_Data_Analysis[[#This Row],[Vacation Reserve]]-2979000)*0.151) -> 59207.461 | R104: =Payroll_Data_Analysis[[#This Row],[Monthly Salary]]*11 -> 1903000 | S104: =IF(Payroll_Data_Analysis[[#This Row],[11-Month Salary]]<=2979000,Payroll_Data_Analysis[[#This Row],[11-Month Salary]]*0.302,2979000*0.302+(Payroll_Data_Analysis[[#This Row],[11-Month Salary]]-2979000)*0.151) -> 574706 | T104: =IF(Payroll_Data_Analysis[[#This Row],[Base Salary (Monthly)]]>=200000,69507,IF(Payroll_Data_Analysis[[#This Row],[Base Salary (Monthly)]]>=145000,52684,35103)) -> 35103 | U104: =Payroll_Data_Analysis[[#This Row],[Annual KPI Bonus Reserve]]+Payroll_Data_Analysis[[#This Row],[Vacation Reserve]]+Payroll_Data_Analysis[[#This Row],[11-Month Salary]] -> 2246651.2 | V104: =Payroll_Data_Analysis[[#This Row],[Payroll Taxes (KPI Bonus)]]+Payroll_Data_Analysis[[#This Row],[Payroll Taxes (Vacation)]]+Payroll_Data_Analysis[[#This Row],[Payroll Taxes (Salary)]] -> 678488.66 | W104: =Payroll_Data_Analysis[[#This Row],[Total Payroll]]+Payroll_Data_Analysis[[#This Row],[Total Payroll Taxes]] -> 2925139.9
A105: Building Operations № 1 | B105: Emp_105 | C105: Department Director | D105: =VLOOKUP(Payroll_Data_Analysis[[#This Row],[Position]],Position_Map!$A$2:$B$58,2,FALSE) -> Management | E105: 1 | F105: 238600 | G105: 145000 | I105: =dataset!$F105-dataset!$J105-dataset!$G105-dataset!$H105 -> 82000 | J105: =dataset!$G105*0.08 -> 11600 | K105: =dataset!$F105*12 -> 2863200 | L105: =IF(dataset!$G105>=200000,38%,IF(dataset!$G105<=145000,12.3%,)) -> 0.123 | M105: =dataset!$G105*L106*12 -> 214020 | N105: =IF(Payroll_Data_Analysis[[#This Row],[Annual KPI Bonus Reserve]]<=2979000,Payroll_Data_Analysis[[#This Row],[Annual KPI Bonus Reserve]]*0.302,2979000*0.302+(Payroll_Data_Analysis[[#This Row],[Annual KPI Bonus Reserve]]-2979000)*0.151) -> 64634.04 | O105: =dataset!$K105+dataset!$M105 -> 3077220 | P105: =Payroll_Data_Analysis[[#This Row],[Annual Salary + KPI Bonus]]/12/29.3*31 -> 271313.48 | Q105: =IF(Payroll_Data_Analysis[[#This Row],[Vacation Reserve]]<=2979000,Payroll_Data_Analysis[[#This Row],[Vacation Reserve]]*0.302,2979000*0.302+(Payroll_Data_Analysis[[#This Row],[Vacation Reserve]]-2979000)*0.151) -> 81936.671 | R105: =Payroll_Data_Analysis[[#This Row],[Monthly Salary]]*11 -> 2624600 | S105: =IF(Payroll_Data_Analysis[[#This Row],[11-Month Salary]]<=2979000,Payroll_Data_Analysis[[#This Row],[11-Month Salary]]*0.302,2979000*0.302+(Payroll_Data_Analysis[[#This Row],[11-Month Salary]]-2979000)*0.151) -> 792629.2 | T105: =IF(Payroll_Data_Analysis[[#This Row],[Base Salary (Monthly)]]>=200000,69507,IF(Payroll_Data_Analysis[[#This Row],[Base Salary (Monthly)]]>=145000,52684,35103)) -> 52684 | U105: =Payroll_Data_Analysis[[#This Row],[Annual KPI Bonus Reserve]]+Payroll_Data_Analysis[[#This Row],[Vacation Reserve]]+Payroll_Data_Analysis[[#This Row],[11-Month Salary]] -> 3109933.5 | V105: =Payroll_Data_Analysis[[#This Row],[Payroll Taxes (KPI Bonus)]]+Payroll_Data_Analysis[[#This Row],[Payroll Taxes (Vacation)]]+Payroll_Data_Analysis[[#This Row],[Payroll Taxes (Salary)]] -> 939199.91 | W105: =Payroll_Data_Analysis[[#This Row],[Total Payroll]]+Payroll_Data_Analysis[[#This Row],[Total Payroll Taxes]] -> 4049133.4
A106: Building Operations № 1 | B106: Emp_106 | C106: Chief Engineer | D106: =VLOOKUP(Payroll_Data_Analysis[[#This Row],[Position]],Position_Map!$A$2:$B$58,2,FALSE) -> Engineering | E106: 1 | F106: 211600 | G106: 145000 | I106: =dataset!$F106-dataset!$J106-dataset!$G106-dataset!$H106 -> 55000 | J106: =dataset!$G106*0.08 -> 11600 | K106: =dataset!$F106*12 -> 2539200 | L106: =IF(dataset!$G106>=200000,38%,IF(dataset!$G106<=145000,12.3%,)) -> 0.123 | M106: =dataset!$G106*L107*12 -> 214020 | N106: =IF(Payroll_Data_Analysis[[#This Row],[Annual KPI Bonus Reserve]]<=2979000,Payroll_Data_Analysis[[#This Row],[Annual KPI Bonus Reserve]]*0.302,2979000*0.302+(Payroll_Data_Analysis[[#This Row],[Annual KPI Bonus Reserve]]-2979000)*0.151) -> 64634.04 | O106: =dataset!$K106+dataset!$M106 -> 2753220 | P106: =Payroll_Data_Analysis[[#This Row],[Annual Salary + KPI Bonus]]/12/29.3*31 -> 242746.93 | Q106: =IF(Payroll_Data_Analysis[[#This Row],[Vacation Reserve]]<=2979000,Payroll_Data_Analysis[[#This Row],[Vacation Reserve]]*0.302,2979000*0.302+(Payroll_Data_Analysis[[#This Row],[Vacation Reserve]]-2979000)*0.151) -> 73309.572 | R106: =Payroll_Data_Analysis[[#This Row],[Monthly Salary]]*11 -> 2327600 | S106: =IF(Payroll_Data_Analysis[[#This Row],[11-Month Salary]]<=2979000,Payroll_Data_Analysis[[#This Row],[11-Month Salary]]*0.302,2979000*0.302+(Payroll_Data_Analysis[[#This Row],[11-Month Salary]]-2979000)*0.151) -> 702935.2 | T106: =IF(Payroll_Data_Analysis[[#This Row],[Base Salary (Monthly)]]>=200000,69507,IF(Payroll_Data_Analysis[[#This Row],[Base Salary (Monthly)]]>=145000,52684,35103)) -> 52684 | U106: =Payroll_Data_Analysis[[#This Row],[Annual KPI Bonus Reserve]]+Payroll_Data_Analysis[[#This Row],[Vacation Reserve]]+Payroll_Data_Analysis[[#This Row],[11-Month Salary]] -> 2784366.9 | V106: =Payroll_Data_Analysis[[#This Row],[Payroll Taxes (KPI Bonus)]]+Payroll_Data_Analysis[[#This Row],[Payroll Taxes (Vacation)]]+Payroll_Data_Analysis[[#This Row],[Payroll Taxes (Salary)]] -> 840878.81 | W106: =Payroll_Data_Analysis[[#This Row],[Total Payroll]]+Payroll_Data_Analysis[[#This Row],[Total Payroll Taxes]] -> 3625245.7
A107: Building Operations № 1 | B107: Emp_107 | C107: Assistant | D107: =VLOOKUP(Payroll_Data_Analysis[[#This Row],[Position]],Position_Map!$A$2:$B$58,2,FALSE) -> Administration | E107: 1 | F107: 261600 | G107: 145000 | I107: =dataset!$F107-dataset!$J107-dataset!$G107-dataset!$H107 -> 105000 | J107: =dataset!$G107*0.08 -> 11600 | K107: =dataset!$F107*12 -> 3139200 | L107: =IF(dataset!$G107>=200000,38%,IF(dataset!$G107<=145000,12.3%,)) -> 0.123 | M107: =dataset!$G107*L108*12 -> 661200 | N107: =IF(Payroll_Data_Analysis[[#This Row],[Annual KPI Bonus Reserve]]<=2979000,Payroll_Data_Analysis[[#This Row],[Annual KPI Bonus Reserve]]*0.302,2979000*0.302+(Payroll_Data_Analysis[[#This Row],[Annual KPI Bonus Reserve]]-2979000)*0.151) -> 199682.4 | O107: =dataset!$K107+dataset!$M107 -> 3800400 | P107: =Payroll_Data_Analysis[[#This Row],[Annual Salary + KPI Bonus]]/12/29.3*31 -> 335075.09 | Q107: =IF(Payroll_Data_Analysis[[#This Row],[Vacation Reserve]]<=2979000,Payroll_Data_Analysis[[#This Row],[Vacation Reserve]]*0.302,2979000*0.302+(Payroll_Data_Analysis[[#This Row],[Vacation Reserve]]-2979000)*0.151) -> 101192.68 | R107: =Payroll_Data_Analysis[[#This Row],[Monthly Salary]]*11 -> 2877600 | S107: =IF(Payroll_Data_Analysis[[#This Row],[11-Month Salary]]<=2979000,Payroll_Data_Analysis[[#This Row],[11-Month Salary]]*0.302,2979000*0.302+(Payroll_Data_Analysis[[#This Row],[11-Month Salary]]-2979000)*0.151) -> 869035.2 | T107: =IF(Payroll_Data_Analysis[[#This Row],[Base Salary (Monthly)]]>=200000,69507,IF(Payroll_Data_Analysis[[#This Row],[Base Salary (Monthly)]]>=145000,52684,35103)) -> 52684 | U107: =Payroll_Data_Analysis[[#This Row],[Annual KPI Bonus Reserve]]+Payroll_Data_Analysis[[#This Row],[Vacation Reserve]]+Payroll_Data_Analysis[[#This Row],[11-Month Salary]] -> 3873875.1 | V107: =Payroll_Data_Analysis[[#This Row],[Payroll Taxes (KPI Bonus)]]+Payroll_Data_Analysis[[#This Row],[Payroll Taxes (Vacation)]]+Payroll_Data_Analysis[[#This Row],[Payroll Taxes (Salary)]] -> 1169910.3 | W107: =Payroll_Data_Analysis[[#This Row],[Total Payroll]]+Payroll_Data_Analysis[[#This Row],[Total Payroll Taxes]] -> 5043785.4
A108: Building Operations № 1 | B108: Emp_108 | C108: Advisor | D108: =VLOOKUP(Payroll_Data_Analysis[[#This Row],[Position]],Position_Map!$A$2:$B$58,2,FALSE) -> Professional | E108: 1 | F108: 301000 | G108: 200000 | I108: =dataset!$F108-dataset!$J108-dataset!$G108-dataset!$H108 -> 85000 | J108: =dataset!$G108*0.08 -> 16000 | K108: =dataset!$F108*12 -> 3612000 | L108: =IF(dataset!$G108>=200000,38%,IF(dataset!$G108<=145000,12.3%,)) -> 0.38 | M108: =dataset!$G108*L109*12 -> 295200 | N108: =IF(Payroll_Data_Analysis[[#This Row],[Annual KPI Bonus Reserve]]<=2979000,Payroll_Data_Analysis[[#This Row],[Annual KPI Bonus Reserve]]*0.302,2979000*0.302+(Payroll_Data_Analysis[[#This Row],[Annual KPI Bonus Reserve]]-2979000)*0.151) -> 89150.4 | O108: =dataset!$K108+dataset!$M108 -> 3907200 | P108: =Payroll_Data_Analysis[[#This Row],[Annual Salary + KPI Bonus]]/12/29.3*31 -> 344491.47 | Q108: =IF(Payroll_Data_Analysis[[#This Row],[Vacation Reserve]]<=2979000,Payroll_Data_Analysis[[#This Row],[Vacation Reserve]]*0.302,2979000*0.302+(Payroll_Data_Analysis[[#This Row],[Vacation Reserve]]-2979000)*0.151) -> 104036.42 | R108: =Payroll_Data_Analysis[[#This Row],[Monthly Salary]]*11 -> 3311000 | S108: =IF(Payroll_Data_Analysis[[#This Row],[11-Month Salary]]<=2979000,Payroll_Data_Analysis[[#This Row],[11-Month Salary]]*0.302,2979000*0.302+(Payroll_Data_Analysis[[#This Row],[11-Month Salary]]-2979000)*0.151) -> 949790 | T108: =IF(Payroll_Data_Analysis[[#This Row],[Base Salary (Monthly)]]>=200000,69507,IF(Payroll_Data_Analysis[[#This Row],[Base Salary (Monthly)]]>=145000,52684,35103)) -> 69507 | U108: =Payroll_Data_Analysis[[#This Row],[Annual KPI Bonus Reserve]]+Payroll_Data_Analysis[[#This Row],[Vacation Reserve]]+Payroll_Data_Analysis[[#This Row],[11-Month Salary]] -> 3950691.5 | V108: =Payroll_Data_Analysis[[#This Row],[Payroll Taxes (KPI Bonus)]]+Payroll_Data_Analysis[[#This Row],[Payroll Taxes (Vacation)]]+Payroll_Data_Analysis[[#This Row],[Payroll Taxes (Salary)]] -> 1142976.8 | W108: =Payroll_Data_Analysis[[#This Row],[Total Payroll]]+Payroll_Data_Analysis[[#This Row],[Total Payroll Taxes]] -> 5093668.3
... A225: Building Operations № 3 | B225: Emp_225 | C225: Building Maintenance Technician | D225: =VLOOKUP(Payroll_Data_Analysis[[#This Row],[Position]],Position_Map!$A$2:$B$58,2,FALSE) -> Technical | E225: 1 | F225: 74000 | G225: 50000 | I225: =dataset!$F225-dataset!$J225-dataset!$G225-dataset!$H225 -> 20000 | J225: =dataset!$G225*0.08 -> 4000 | K225: =dataset!$F225*12 -> 888000 | L225: =IF(dataset!$G225>=200000,38%,IF(dataset!$G225<=145000,12.3%,)) -> 0.123 | M225: =dataset!$G225*L226*12 -> 73800 | N225: =IF(Payroll_Data_Analysis[[#This Row],[Annual KPI Bonus Reserve]]<=2979000,Payroll_Data_Analysis[[#This Row],[Annual KPI Bonus Reserve]]*0.302,2979000*0.302+(Payroll_Data_Analysis[[#This Row],[Annual KPI Bonus Reserve]]-2979000)*0.151) -> 22287.6 | O225: =dataset!$K225+dataset!$M225 -> 961800 | P225: =Payroll_Data_Analysis[[#This Row],[Annual Salary + KPI Bonus]]/12/29.3*31 -> 84800.341 | Q225: =IF(Payroll_Data_Analysis[[#This Row],[Vacation Reserve]]<=2979000,Payroll_Data_Analysis[[#This Row],[Vacation Reserve]]*0.302,2979000*0.302+(Payroll_Data_Analysis[[#This Row],[Vacation Reserve]]-2979000)*0.151) -> 25609.703 | R225: =Payroll_Data_Analysis[[#This Row],[Monthly Salary]]*11 -> 814000 | S225: =IF(Payroll_Data_Analysis[[#This Row],[11-Month Salary]]<=2979000,Payroll_Data_Analysis[[#This Row],[11-Month Salary]]*0.302,2979000*0.302+(Payroll_Data_Analysis[[#This Row],[11-Month Salary]]-2979000)*0.151) -> 245828 | T225: =IF(Payroll_Data_Analysis[[#This Row],[Base Salary (Monthly)]]>=200000,69507,IF(Payroll_Data_Analysis[[#This Row],[Base Salary (Monthly)]]>=145000,52684,35103)) -> 35103 | U225: =Payroll_Data_Analysis[[#This Row],[Annual KPI Bonus Reserve]]+Payroll_Data_Analysis[[#This Row],[Vacation Reserve]]+Payroll_Data_Analysis[[#This Row],[11-Month Salary]] -> 972600.34 | V225: =Payroll_Data_Analysis[[#This Row],[Payroll Taxes (KPI Bonus)]]+Payroll_Data_Analysis[[#This Row],[Payroll Taxes (Vacation)]]+Payroll_Data_Analysis[[#This Row],[Payroll Taxes (Salary)]] -> 293725.3 | W225: =Payroll_Data_Analysis[[#This Row],[Total Payroll]]+Payroll_Data_Analysis[[#This Row],[Total Payroll Taxes]] -> 1266325.6
